<?xml version="1.0" encoding="utf-8"?>
<!-- This URDF was automatically created by SolidWorks to URDF Exporter! Originally created by Stephen Brawner (brawner@gmail.com) 
     Commit Version: 1.6.0-4-g7f85cfe  Build Version: 1.6.7995.38578
     For more information, please see http://wiki.ros.org/sw_urdf_exporter -->
<robot
  name="Nhap1803">
  <link
    name="base_link">
    <inertial>
      <origin
        xyz="-0.0003195 -0.0019358 0.12546"
        rpy="0 0 0" />
      <mass
        value="14.198" />
      <inertia
        ixx="1.1146"
        ixy="-1.5288E-07"
        ixz="-8.9692E-10"
        iyy="0.59567"
        iyz="4.2239E-08"
        izz="1.5215" />
    </inertial>
    <visual>
      <origin
        xyz="0 0 0"
        rpy="0 0 0" />
      <geometry>
        <mesh
          filename="package://Nhap1803/meshes/base_link.STL" />
      </geometry>
      <material
        name="">
        <color
          rgba="0.56078 0.56078 0.56078 1" />
      </material>
    </visual>
    <collision>
      <origin
        xyz="0 0 0"
        rpy="0 0 0" />
      <geometry>
        <mesh
          filename="package://Nhap1803/meshes/base_link.STL" />
      </geometry>
    </collision>
  </link>
  <link
    name="leftt_wheel">
    <inertial>
      <origin
        xyz="-6.9389E-18 2.4287E-18 -0.0013124"
        rpy="0 0 0" />
      <mass
        value="0.5" />
      <inertia
        ixx="0.0055201"
        ixy="-1.8612E-21"
        ixz="3.0675E-19"
        iyy="0.0055201"
        iyz="2.7061E-19"
        izz="0.010589" />
    </inertial>
    <visual>
      <origin
        xyz="0 0 0"
        rpy="0 0 0" />
      <geometry>
        <mesh
          filename="package://Nhap1803/meshes/leftt_wheel.STL" />
      </geometry>
      <material
        name="">
        <color
          rgba="0.79216 0.81961 0.93333 1" />
      </material>
    </visual>
    <collision>
      <origin
        xyz="0 0 0"
        rpy="0 0 0" />
      <geometry>
        <mesh
          filename="package://Nhap1803/meshes/leftt_wheel.STL" />
      </geometry>
    </collision>
  </link>
  <joint
    name="leftwheel"
    type="continuous">
    <origin
      xyz="-0.239 0 0.048"
      rpy="3.1416 -1.5708 0" />
    <parent
      link="base_link" />
    <child
      link="leftt_wheel" />
    <axis
      xyz="0 0 -1" />
    <limit
      effort="10"
      velocity="10" />
    <dynamics
      damping="0.1"
      friction="0.1" />
  </joint>
  <link
    name="right_wheel">
    <inertial>
      <origin
        xyz="-6.9389E-18 -3.794E-18 0.0013124"
        rpy="0 0 0" />
      <mass
        value="0.5" />
      <inertia
        ixx="0.0055201"
        ixy="1.4476E-21"
        ixz="-6.1012E-19"
        iyy="0.0055201"
        iyz="4.8495E-19"
        izz="0.010589" />
    </inertial>
    <visual>
      <origin
        xyz="0 0 0"
        rpy="0 0 0" />
      <geometry>
        <mesh
          filename="package://Nhap1803/meshes/right_wheel.STL" />
      </geometry>
      <material
        name="">
        <color
          rgba="0.79216 0.81961 0.93333 1" />
      </material>
    </visual>
    <collision>
      <origin
        xyz="0 0 0"
        rpy="0 0 0" />
      <geometry>
        <mesh
          filename="package://Nhap1803/meshes/right_wheel.STL" />
      </geometry>
    </collision>
  </link>
  <joint
    name="rightwheel"
    type="continuous">
    <origin
      xyz="0.239 0 0.048"
      rpy="3.1416 -1.5708 0" />
    <parent
      link="base_link" />
    <child
      link="right_wheel" />
    <axis
      xyz="0 0 1" />
    <limit
      effort="10"
      velocity="10" />
    <dynamics
      damping="0.1"
      friction="0.1" />
  </joint>
  <link
    name="caster1">
    <inertial>
      <origin
        xyz="3.3798E-06 -0.0019114 -0.0084881"
        rpy="0 0 0" />
      <mass
        value="0.021452" />
      <inertia
        ixx="5.9535E-06"
        ixy="-6.0783E-11"
        ixz="5.2287E-11"
        iyy="5.3578E-06"
        iyz="-6.0929E-07"
        izz="8.8365E-06" />
    </inertial>
    <visual>
      <origin
        xyz="0 0 0"
        rpy="0 0 0" />
      <geometry>
        <mesh
          filename="package://Nhap1803/meshes/caster1.STL" />
      </geometry>
      <material
        name="">
        <color
          rgba="0.68627 0.68627 0.68627 1" />
      </material>
    </visual>
    <collision>
      <origin
        xyz="0 0 0"
        rpy="0 0 0" />
      <geometry>
        <mesh
          filename="package://Nhap1803/meshes/caster1.STL" />
      </geometry>
    </collision>
  </link>
  <joint
    name="casterjoint1"
    type="continuous">
    <origin
      xyz="-0.2365 0.3445 0"
      rpy="0 0 0" />
    <parent
      link="base_link" />
    <child
      link="caster1" />
    <axis
      xyz="0 0 1" />
    <limit
      effort="10"
      velocity="10" />
  </joint>
  <link
    name="caster_wheel1">
    <inertial>
      <origin
        xyz="-2.2118E-12 4.7003E-06 3.801E-11"
        rpy="0 0 0" />
      <mass
        value="0.027548" />
      <inertia
        ixx="5.0367E-06"
        ixy="5.9339E-16"
        ixz="-8.758E-17"
        iyy="5.0354E-06"
        iyz="5.0365E-15"
        izz="8.536E-06" />
    </inertial>
    <visual>
      <origin
        xyz="0 0 0"
        rpy="0 0 0" />
      <geometry>
        <mesh
          filename="package://Nhap1803/meshes/caster_wheel1.STL" />
      </geometry>
      <material
        name="">
        <color
          rgba="0.79216 0.81961 0.93333 1" />
      </material>
    </visual>
    <collision>
      <origin
        xyz="0 0 0"
        rpy="0 0 0" />
      <geometry>
        <mesh
          filename="package://Nhap1803/meshes/caster_wheel1.STL" />
      </geometry>
    </collision>
  </link>
  <joint
    name="casterwheel1"
    type="continuous">
    <origin
      xyz="0 -0.017 -0.039"
      rpy="3.1416 -1.5708 0" />
    <parent
      link="caster1" />
    <child
      link="caster_wheel1" />
    <axis
      xyz="0 0 -1" />
    <limit
      effort="10"
      velocity="10" />
    <dynamics
      damping="0.1"
      friction="0.1" />
  </joint>
  <link
    name="caster2">
    <inertial>
      <origin
        xyz="3.3798E-06 -0.0019114 -0.0084881"
        rpy="0 0 0" />
      <mass
        value="0.021452" />
      <inertia
        ixx="5.9535E-06"
        ixy="-6.0783E-11"
        ixz="5.2287E-11"
        iyy="5.3578E-06"
        iyz="-6.0929E-07"
        izz="8.8365E-06" />
    </inertial>
    <visual>
      <origin
        xyz="0 0 0"
        rpy="0 0 0" />
      <geometry>
        <mesh
          filename="package://Nhap1803/meshes/caster2.STL" />
      </geometry>
      <material
        name="">
        <color
          rgba="0.68627 0.68627 0.68627 1" />
      </material>
    </visual>
    <collision>
      <origin
        xyz="0 0 0"
        rpy="0 0 0" />
      <geometry>
        <mesh
          filename="package://Nhap1803/meshes/caster2.STL" />
      </geometry>
    </collision>
  </link>
  <joint
    name="casterjoint2"
    type="continuous">
    <origin
      xyz="0.2365 0.3445 0"
      rpy="0 0 0" />
    <parent
      link="base_link" />
    <child
      link="caster2" />
    <axis
      xyz="0 0 1" />
    <limit
      effort="10"
      velocity="10" />
  </joint>
  <link
    name="caster_wheel2">
    <inertial>
      <origin
        xyz="-2.2118E-12 4.7003E-06 3.801E-11"
        rpy="0 0 0" />
      <mass
        value="0.027548" />
      <inertia
        ixx="5.0367E-06"
        ixy="5.9339E-16"
        ixz="-8.758E-17"
        iyy="5.0354E-06"
        iyz="5.0365E-15"
        izz="8.536E-06" />
    </inertial>
    <visual>
      <origin
        xyz="0 0 0"
        rpy="0 0 0" />
      <geometry>
        <mesh
          filename="package://Nhap1803/meshes/caster_wheel2.STL" />
      </geometry>
      <material
        name="">
        <color
          rgba="0.79216 0.81961 0.93333 1" />
      </material>
    </visual>
    <collision>
      <origin
        xyz="0 0 0"
        rpy="0 0 0" />
      <geometry>
        <mesh
          filename="package://Nhap1803/meshes/caster_wheel2.STL" />
      </geometry>
    </collision>
  </link>
  <joint
    name="casterwheel2"
    type="continuous">
    <origin
      xyz="0 -0.017 -0.039"
      rpy="3.1416 -1.5708 0" />
    <parent
      link="caster2" />
    <child
      link="caster_wheel2" />
    <axis
      xyz="0 0 -1" />
    <limit
      effort="10"
      velocity="10" />
    <dynamics
      damping="0.1"
      friction="0.1" />
  </joint>
  <link
    name="caster3">
    <inertial>
      <origin
        xyz="3.3798E-06 -0.0019114 -0.0084881"
        rpy="0 0 0" />
      <mass
        value="0.021452" />
      <inertia
        ixx="5.9535E-06"
        ixy="-6.0783E-11"
        ixz="5.2287E-11"
        iyy="5.3578E-06"
        iyz="-6.0929E-07"
        izz="8.8365E-06" />
    </inertial>
    <visual>
      <origin
        xyz="0 0 0"
        rpy="0 0 0" />
      <geometry>
        <mesh
          filename="package://Nhap1803/meshes/caster3.STL" />
      </geometry>
      <material
        name="">
        <color
          rgba="0.68627 0.68627 0.68627 1" />
      </material>
    </visual>
    <collision>
      <origin
        xyz="0 0 0"
        rpy="0 0 0" />
      <geometry>
        <mesh
          filename="package://Nhap1803/meshes/caster3.STL" />
      </geometry>
    </collision>
  </link>
  <joint
    name="casterjoint3"
    type="continuous">
    <origin
      xyz="-0.2365 -0.3445 0"
      rpy="0 0 0" />
    <parent
      link="base_link" />
    <child
      link="caster3" />
    <axis
      xyz="0 0 -1" />
    <limit
      effort="10"
      velocity="10" />
  </joint>
  <link
    name="caster_wheel3">
    <inertial>
      <origin
        xyz="-2.2118E-12 4.7003E-06 3.801E-11"
        rpy="0 0 0" />
      <mass
        value="0.027548" />
      <inertia
        ixx="5.0367E-06"
        ixy="5.9339E-16"
        ixz="-8.7582E-17"
        iyy="5.0354E-06"
        iyz="5.0365E-15"
        izz="8.536E-06" />
    </inertial>
    <visual>
      <origin
        xyz="0 0 0"
        rpy="0 0 0" />
      <geometry>
        <mesh
          filename="package://Nhap1803/meshes/caster_wheel3.STL" />
      </geometry>
      <material
        name="">
        <color
          rgba="0.79216 0.81961 0.93333 1" />
      </material>
    </visual>
    <collision>
      <origin
        xyz="0 0 0"
        rpy="0 0 0" />
      <geometry>
        <mesh
          filename="package://Nhap1803/meshes/caster_wheel3.STL" />
      </geometry>
    </collision>
  </link>
  <joint
    name="casterwheel3"
    type="continuous">
    <origin
      xyz="0 -0.017 -0.039"
      rpy="3.1416 -1.5708 0" />
    <parent
      link="caster3" />
    <child
      link="caster_wheel3" />
    <axis
      xyz="0 0 -1" />
    <limit
      effort="10"
      velocity="10" />
    <dynamics
      damping="0.1"
      friction="0.1" />
  </joint>
  <link
    name="caster4">
    <inertial>
      <origin
        xyz="3.3798E-06 -0.0019114 -0.0084881"
        rpy="0 0 0" />
      <mass
        value="0.021452" />
      <inertia
        ixx="5.9535E-06"
        ixy="-6.0783E-11"
        ixz="5.2287E-11"
        iyy="5.3578E-06"
        iyz="-6.0929E-07"
        izz="8.8365E-06" />
    </inertial>
    <visual>
      <origin
        xyz="0 0 0"
        rpy="0 0 0" />
      <geometry>
        <mesh
          filename="package://Nhap1803/meshes/caster4.STL" />
      </geometry>
      <material
        name="">
        <color
          rgba="0.68627 0.68627 0.68627 1" />
      </material>
    </visual>
    <collision>
      <origin
        xyz="0 0 0"
        rpy="0 0 0" />
      <geometry>
        <mesh
          filename="package://Nhap1803/meshes/caster4.STL" />
      </geometry>
    </collision>
  </link>
  <joint
    name="casterjoint4"
    type="continuous">
    <origin
      xyz="0.2365 -0.3445 0"
      rpy="0 0 0" />
    <parent
      link="base_link" />
    <child
      link="caster4" />
    <axis
      xyz="0 0 -1" />
    <limit
      effort="10"
      velocity="10" />
  </joint>
  <link
    name="caster_wheel4">
    <inertial>
      <origin
        xyz="-2.2118E-12 4.7003E-06 3.801E-11"
        rpy="0 0 0" />
      <mass
        value="0.027548" />
      <inertia
        ixx="5.0367E-06"
        ixy="5.9339E-16"
        ixz="-8.758E-17"
        iyy="5.0354E-06"
        iyz="5.0365E-15"
        izz="8.536E-06" />
    </inertial>
    <visual>
      <origin
        xyz="0 0 0"
        rpy="0 0 0" />
      <geometry>
        <mesh
          filename="package://Nhap1803/meshes/caster_wheel4.STL" />
      </geometry>
      <material
        name="">
        <color
          rgba="0.79216 0.81961 0.93333 1" />
      </material>
    </visual>
    <collision>
      <origin
        xyz="0 0 0"
        rpy="0 0 0" />
      <geometry>
        <mesh
          filename="package://Nhap1803/meshes/caster_wheel4.STL" />
      </geometry>
    </collision>
  </link>
  <joint
    name="casterwheel4"
    type="continuous">
    <origin
      xyz="0 -0.017 -0.039"
      rpy="3.1416 -1.5708 0" />
    <parent
      link="caster4" />
    <child
      link="caster_wheel4" />
    <axis
      xyz="0 0 -1" />
    <limit
      effort="10"
      velocity="10" />
    <dynamics
      damping="0.1"
      friction="0.1" />
  </joint>
</robot>